Workbook

Sheet Dashboard
A1: VATflow | United Fintec — UK VAT Return Template
A2: All VAT Schemes · Making Tax Digital Compliant · Boxes 1–9 Auto-Calculated
A4: BUSINESS INFORMATION
A5: Business / Trading Name
A6: VAT Registration Number (VRN)
A7: Company Registration Number
A8: Registered Address
A9: Contact Email
A10: VAT Period Start
A11: VAT Period End
A12: Submission Due Date
A14: VAT ACCOUNTING SCHEME SELECTOR
A15: VAT Accounting Scheme | B15: Standard (Invoice Basis)
A16: Flat Rate % (FRS only — enter as decimal e.g. 0.165 = 16.5%) | B16: 0.165
A18: VAT RETURN SUMMARY — 9 BOXES (live links from VAT_Return sheet)
A19: Box | B19: Description | F19: £ Amount
A20: Box 1 | B20: VAT due on sales and other outputs | F20: =VAT_Return!C15 -> 0
A21: Box 2 | B21: VAT on EC acquisitions (Northern Ireland only) | F21: =VAT_Return!C16 -> 0
A22: Box 3 | B22: Total VAT due [AUTO = Box 1 + Box 2] | F22: =VAT_Return!C17 -> 0
A23: Box 4 | B23: VAT reclaimed on purchases and inputs | F23: =VAT_Return!C18 -> 0
A24: Box 5 | B24: NET VAT PAYABLE [AUTO = Box 3 − Box 4] | F24: =VAT_Return!C19 -> 0
A25: Box 6 | B25: Total value of sales excl. VAT | F25: =VAT_Return!C20 -> 0
A26: Box 7 | B26: Total value of purchases excl. VAT | F26: =VAT_Return!C21 -> 0
A27: Box 8 | B27: Goods supplied to EC member states excl. VAT | F27: =VAT_Return!C22 -> 0
A28: Box 9 | B28: Goods acquired from EC member states excl. VAT (NI only) | F28: =VAT_Return!C23 -> 0
A30: COLOUR CODING GUIDE
A31: AMBER background = INPUT cell — you enter data here | B31: GREEN background = AUTO formula — do not edit | C31: BLUE text = Direct input value | D31: GREEN text = Cross-sheet formula link
A34: VATflow by United Fintec Limited · contact@unitedfintec.com · unitedfintec.com · © 2025 United Fintec Limited

Sheet VAT_Return
A1: VAT RETURN — 9 BOX CALCULATION ENGINE
A2: Formulas link to Sales and Expenses sheets · Arithmetic checks auto-validate · Do NOT override AUTO cells
A4: RETURN DETAILS (linked from Dashboard sheet)
A5: Business Name | B5: =Dashboard!B5 -> 0
A6: VRN | B6: =Dashboard!B6 -> 0
A7: VAT Scheme | B7: =Dashboard!B15 -> Standard (Invoice Basis)
A8: Period Start | B8: =Dashboard!B10 -> 0
A9: Period End | B9: =Dashboard!B11 -> 0
A10: Due Date | B10: =Dashboard!B12 -> 0
A12: 9-BOX VAT RETURN — SUBMISSION VALUES
A13: Box | B13: Description | C13: £ Amount | D13: Scheme Notes
A15: 1 | B15: VAT due on sales and other outputs | C15: =IF(IFERROR(Dashboard!B15,"")="Flat Rate Scheme",ROUND(IFERROR(Sales!I3,0)*IFERROR(Dashboard!B16,0),2),ROUND(IFERROR(Sales!H3,0),2)) -> 0 | D15: FRS: Gross Sales Total × FRS%. Standard/Cash/Annual/Retail: sum of VAT column (col H) from Sales.
A16: 2 | B16: VAT on EC acquisitions (Northern Ireland only) | C16: =ROUND(IFERROR(Expenses!I3,0),2) -> 0 | D16: NI Windsor Framework traders only. Enter in Sales sheet col J. All others: £0.
A17: 3 | B17: Total VAT due [AUTO = Box 1 + Box 2] | C17: =ROUND(C15+C16,2) -> 0 | D17: AUTOMATICALLY CALCULATED — do not override.
A18: 4 | B18: VAT reclaimed on purchases and inputs | C18: =ROUND(IFERROR(Expenses!H3,0),2) -> 0 | D18: FRS: £0 normally (except capital goods ≥£2,000 incl. VAT, marked Capital Goods FRS in Expenses). Standard/Cash: full recovery.
A19: 5 | B19: Net VAT payable or reclaimable [AUTO = Box 3 − Box 4] | C19: =ROUND(C17-C18,2) -> 0 | D19: =IF(ROUND(C17,2)=ROUND(C15+C16,2),"✓ PASS","✗ ERROR: Check Boxes 1 & 2") -> ✓ PASS
A20: 6 | B20: Total value of sales and outputs, excluding VAT | C20: =ROUND(IFERROR(Sales!F3,0),2) -> 0 | D20: =IF(ROUND(C19,2)=ROUND(C17-C18,2),"✓ PASS","✗ ERROR: Check Boxes 3 & 4") -> ✓ PASS
A21: 7 | B21: Total value of purchases and inputs, excluding VAT | C21: =ROUND(IFERROR(Expenses!F3,0),2) -> 0 | D21: Net purchases total. Linked from Expenses sheet column F.
A22: 8 | B22: Goods supplied to EC member states, excluding VAT | C22: =ROUND(IFERROR(Sales!J3,0),2) -> 0 | D22: Post-Brexit EU goods exports. Enter in Sales sheet col J.
A23: 9 | B23: Total acquisitions from EC member states, excl. VAT (NI only) | C23: =ROUND(IFERROR(Expenses!I3,0),2) -> 0 | D23: NI Windsor Framework only. Enter in Expenses sheet col I.
A25: ARITHMETIC VALIDATION CHECKS
A26: Box 3 = Box 1 + Box 2 | D26: =IF(ROUND(C17,2)=ROUND(C15+C16,2),"✓ PASS","✗ ERROR: Check Boxes 1 & 2") -> ✓ PASS
A27: Box 5 = Box 3 − Box 4 | D27: =IF(ROUND(C19,2)=ROUND(C17-C18,2),"✓ PASS","✗ ERROR: Check Boxes 3 & 4") -> ✓ PASS
A28: All boxes ≥ 0 | D28: =IF(AND(C15>=0,C16>=0,C17>=0,C18>=0,C20>=0,C21>=0),"✓ PASS","⚠ CHECK: Negative value") -> ✓ PASS
A31: VATflow by United Fintec Limited · contact@unitedfintec.com · unitedfintec.com · © 2025 United Fintec Limited

Sheet Sales
A1: SALES REGISTER — VATflow by United Fintec
A2: Enter each sales invoice below · VAT and Gross auto-calculate · Net Sales feeds Box 6 · VAT Amount feeds Box 1
A3: TOTALS | E3: =SUM(E4:E203) -> 0 | F3: =SUM(F4:F203) -> 0 | H3: =SUM(H4:H203) -> 0 | I3: =SUM(I4:I203) -> 0 | J3: =SUM(J4:J203) -> 0
A4: 1 | B4: Invoice No. | C4: Customer / Client Name | D4: Invoice Date | E4: Net Amount £ (Enter Here) | F4: =IF(ISNUMBER(E4),E4,0) -> 0 | G4: 20% | H4: =IF(ISNUMBER(E4),ROUND(E4*IF(G4="20%",0.2,IF(G4="5%",0.05,0)),2),0) -> 0 | I4: =IF(ISNUMBER(E4),E4+H4,0) -> 0 | J4: EC Supply £ (→ Box 8) | K4: Category
A5: 2 | F5: =IF(ISNUMBER(E5),E5,0) -> 0 | G5: 20% | H5: =IF(ISNUMBER(E5),ROUND(E5*IF(G5="20%",0.2,IF(G5="5%",0.05,0)),2),0) -> 0 | I5: =IF(ISNUMBER(E5),E5+H5,0) -> 0
A6: 3 | F6: =IF(ISNUMBER(E6),E6,0) -> 0 | G6: 20% | H6: =IF(ISNUMBER(E6),ROUND(E6*IF(G6="20%",0.2,IF(G6="5%",0.05,0)),2),0) -> 0 | I6: =IF(ISNUMBER(E6),E6+H6,0) -> 0
A7: 4 | F7: =IF(ISNUMBER(E7),E7,0) -> 0 | G7: 20% | H7: =IF(ISNUMBER(E7),ROUND(E7*IF(G7="20%",0.2,IF(G7="5%",0.05,0)),2),0) -> 0 | I7: =IF(ISNUMBER(E7),E7+H7,0) -> 0
A8: 5 | F8: =IF(ISNUMBER(E8),E8,0) -> 0 | G8: 20% | H8: =IF(ISNUMBER(E8),ROUND(E8*IF(G8="20%",0.2,IF(G8="5%",0.05,0)),2),0) -> 0 | I8: =IF(ISNUMBER(E8),E8+H8,0) -> 0
A9: 6 | F9: =IF(ISNUMBER(E9),E9,0) -> 0 | G9: 20% | H9: =IF(ISNUMBER(E9),ROUND(E9*IF(G9="20%",0.2,IF(G9="5%",0.05,0)),2),0) -> 0 | I9: =IF(ISNUMBER(E9),E9+H9,0) -> 0
A10: 7 | F10: =IF(ISNUMBER(E10),E10,0) -> 0 | G10: 20% | H10: =IF(ISNUMBER(E10),ROUND(E10*IF(G10="20%",0.2,IF(G10="5%",0.05,0)),2),0) -> 0 | I10: =IF(ISNUMBER(E10),E10+H10,0) -> 0
A11: 8 | F11: =IF(ISNUMBER(E11),E11,0) -> 0 | G11: 20% | H11: =IF(ISNUMBER(E11),ROUND(E11*IF(G11="20%",0.2,IF(G11="5%",0.05,0)),2),0) -> 0 | I11: =IF(ISNUMBER(E11),E11+H11,0) -> 0
A12: 9 | F12: =IF(ISNUMBER(E12),E12,0) -> 0 | G12: 20% | H12: =IF(ISNUMBER(E12),ROUND(E12*IF(G12="20%",0.2,IF(G12="5%",0.05,0)),2),0) -> 0 | I12: =IF(ISNUMBER(E12),E12+H12,0) -> 0
A13: 10 | F13: =IF(ISNUMBER(E13),E13,0) -> 0 | G13: 20% | H13: =IF(ISNUMBER(E13),ROUND(E13*IF(G13="20%",0.2,IF(G13="5%",0.05,0)),2),0) -> 0 | I13: =IF(ISNUMBER(E13),E13+H13,0) -> 0
A14: 11 | F14: =IF(ISNUMBER(E14),E14,0) -> 0 | G14: 20% | H14: =IF(ISNUMBER(E14),ROUND(E14*IF(G14="20%",0.2,IF(G14="5%",0.05,0)),2),0) -> 0 | I14: =IF(ISNUMBER(E14),E14+H14,0) -> 0
A15: 12 | F15: =IF(ISNUMBER(E15),E15,0) -> 0 | G15: 20% | H15: =IF(ISNUMBER(E15),ROUND(E15*IF(G15="20%",0.2,IF(G15="5%",0.05,0)),2),0) -> 0 | I15: =IF(ISNUMBER(E15),E15+H15,0) -> 0
A16: 13 | F16: =IF(ISNUMBER(E16),E16,0) -> 0 | G16: 20% | H16: =IF(ISNUMBER(E16),ROUND(E16*IF(G16="20%",0.2,IF(G16="5%",0.05,0)),2),0) -> 0 | I16: =IF(ISNUMBER(E16),E16+H16,0) -> 0
... A203: 200 | F203: =IF(ISNUMBER(E203),E203,0) -> 0 | G203: 20% | H203: =IF(ISNUMBER(E203),ROUND(E203*IF(G203="20%",0.2,IF(G203="5%",0.05,0)),2),0) -> 0 | I203: =IF(ISNUMBER(E203),E203+H203,0) -> 0
A205: VATflow by United Fintec Limited · contact@unitedfintec.com · unitedfintec.com · © 2025 United Fintec Limited

Sheet Expenses
A1: EXPENSES & PURCHASES REGISTER — VATflow by United Fintec
A2: ⚠ FRS: Flat Rate traders CANNOT normally claim input VAT (Box 4 = £0). Exception: single capital goods purchase ≥ £2,000 incl. VAT — select 'Capital Goods FRS'. Standard / Cash / Annual / Retail: select 'Claimable' — VAT auto-adds to Box 4.
A3: TOTALS | E3: =SUM(E4:E203) -> 0 | F3: =SUM(F4:F203) -> 0 | H3: =SUMIF(J4:J203,"Claimable",H4:H203)+SUMIF(J4:J203,"Capital Goods FRS",H4:H203) -> 0 | I3: =SUM(I4:I203) -> 0
A4: 1 | B4: Receipt/Inv No. | C4: Supplier Name | D4: Purchase Date | E4: Net Amount £ (Enter Here) | F4: =IF(ISNUMBER(E4),E4,0) -> 0 | G4: 20% | H4: =IF(ISNUMBER(E4),ROUND(E4*IF(G4="20%",0.2,IF(G4="5%",0.05,0)),2),0) -> 0 | I4: =IF(ISNUMBER(E4),E4+H4,0) -> 0 | J4: EC Acq Type | K4: Not Claimable (FRS)
A5: 2 | F5: =IF(ISNUMBER(E5),E5,0) -> 0 | G5: 20% | H5: =IF(ISNUMBER(E5),ROUND(E5*IF(G5="20%",0.2,IF(G5="5%",0.05,0)),2),0) -> 0 | I5: =IF(ISNUMBER(E5),E5+H5,0) -> 0 | K5: Not Claimable (FRS)
A6: 3 | F6: =IF(ISNUMBER(E6),E6,0) -> 0 | G6: 20% | H6: =IF(ISNUMBER(E6),ROUND(E6*IF(G6="20%",0.2,IF(G6="5%",0.05,0)),2),0) -> 0 | I6: =IF(ISNUMBER(E6),E6+H6,0) -> 0 | K6: Not Claimable (FRS)
A7: 4 | F7: =IF(ISNUMBER(E7),E7,0) -> 0 | G7: 20% | H7: =IF(ISNUMBER(E7),ROUND(E7*IF(G7="20%",0.2,IF(G7="5%",0.05,0)),2),0) -> 0 | I7: =IF(ISNUMBER(E7),E7+H7,0) -> 0 | K7: Not Claimable (FRS)
A8: 5 | F8: =IF(ISNUMBER(E8),E8,0) -> 0 | G8: 20% | H8: =IF(ISNUMBER(E8),ROUND(E8*IF(G8="20%",0.2,IF(G8="5%",0.05,0)),2),0) -> 0 | I8: =IF(ISNUMBER(E8),E8+H8,0) -> 0 | K8: Not Claimable (FRS)
A9: 6 | F9: =IF(ISNUMBER(E9),E9,0) -> 0 | G9: 20% | H9: =IF(ISNUMBER(E9),ROUND(E9*IF(G9="20%",0.2,IF(G9="5%",0.05,0)),2),0) -> 0 | I9: =IF(ISNUMBER(E9),E9+H9,0) -> 0 | K9: Not Claimable (FRS)
A10: 7 | F10: =IF(ISNUMBER(E10),E10,0) -> 0 | G10: 20% | H10: =IF(ISNUMBER(E10),ROUND(E10*IF(G10="20%",0.2,IF(G10="5%",0.05,0)),2),0) -> 0 | I10: =IF(ISNUMBER(E10),E10+H10,0) -> 0 | K10: Not Claimable (FRS)
A11: 8 | F11: =IF(ISNUMBER(E11),E11,0) -> 0 | G11: 20% | H11: =IF(ISNUMBER(E11),ROUND(E11*IF(G11="20%",0.2,IF(G11="5%",0.05,0)),2),0) -> 0 | I11: =IF(ISNUMBER(E11),E11+H11,0) -> 0 | K11: Not Claimable (FRS)
A12: 9 | F12: =IF(ISNUMBER(E12),E12,0) -> 0 | G12: 20% | H12: =IF(ISNUMBER(E12),ROUND(E12*IF(G12="20%",0.2,IF(G12="5%",0.05,0)),2),0) -> 0 | I12: =IF(ISNUMBER(E12),E12+H12,0) -> 0 | K12: Not Claimable (FRS)
A13: 10 | F13: =IF(ISNUMBER(E13),E13,0) -> 0 | G13: 20% | H13: =IF(ISNUMBER(E13),ROUND(E13*IF(G13="20%",0.2,IF(G13="5%",0.05,0)),2),0) -> 0 | I13: =IF(ISNUMBER(E13),E13+H13,0) -> 0 | K13: Not Claimable (FRS)
A14: 11 | F14: =IF(ISNUMBER(E14),E14,0) -> 0 | G14: 20% | H14: =IF(ISNUMBER(E14),ROUND(E14*IF(G14="20%",0.2,IF(G14="5%",0.05,0)),2),0) -> 0 | I14: =IF(ISNUMBER(E14),E14+H14,0) -> 0 | K14: Not Claimable (FRS)
A15: 12 | F15: =IF(ISNUMBER(E15),E15,0) -> 0 | G15: 20% | H15: =IF(ISNUMBER(E15),ROUND(E15*IF(G15="20%",0.2,IF(G15="5%",0.05,0)),2),0) -> 0 | I15: =IF(ISNUMBER(E15),E15+H15,0) -> 0 | K15: Not Claimable (FRS)
A16: 13 | F16: =IF(ISNUMBER(E16),E16,0) -> 0 | G16: 20% | H16: =IF(ISNUMBER(E16),ROUND(E16*IF(G16="20%",0.2,IF(G16="5%",0.05,0)),2),0) -> 0 | I16: =IF(ISNUMBER(E16),E16+H16,0) -> 0 | K16: Not Claimable (FRS)
... A203: 200 | F203: =IF(ISNUMBER(E203),E203,0) -> 0 | G203: 20% | H203: =IF(ISNUMBER(E203),ROUND(E203*IF(G203="20%",0.2,IF(G203="5%",0.05,0)),2),0) -> 0 | I203: =IF(ISNUMBER(E203),E203+H203,0) -> 0 | K203: Not Claimable (FRS)
A205: VATflow by United Fintec Limited · contact@unitedfintec.com · unitedfintec.com · © 2025 United Fintec Limited

Sheet FRS_Calculator
A1: FLAT RATE SCHEME (FRS) CALCULATOR — HMRC VAT Notice 733
A2: Enter your sector rate below · All values link from the Sales and Dashboard sheets
A4: FRS CALCULATION
A5: Gross Sales Total (incl. VAT) — from Sales sheet | C5: =IFERROR(Sales!I3,0) -> 0
A6: FRS Percentage — from Dashboard | C6: =Dashboard!B16 -> 0.165
A7: VAT Payable (Box 1) = Gross × FRS% | C7: =ROUND(IFERROR(C5,0)*IFERROR(C6,0),2) -> 0
A8: VAT Charged to Customers (20% standard) | C8: =ROUND(IFERROR(Sales!F3,0)*0.2,2) -> 0
A9: FRS SAVING vs Standard Rate (Box 1 saving) | C9: =ROUND(IFERROR(C8,0)-IFERROR(C7,0),2) -> 0
A10: Net Sales (excl. VAT) — from Sales sheet | C10: =IFERROR(Sales!F3,0) -> 0
A12: HMRC FRS SECTOR PERCENTAGES (2025)
A13: Business Sector | C13: FRS Rate | D13: Limited Cost Trader Rate | E13: Notes
A14: Accountancy / bookkeeping | C14: 14.5% | D14: 16.5% | E14: If goods < 2% turnover
A15: IT & computer services | C15: 14.5% | D15: 16.5% | E15: If goods < 2% turnover
A16: Management consultancy | C16: 14.0% | D16: 16.5% | E16: If goods < 2% turnover
A17: Financial services | C17: 13.5% | D17: 16.5% | E17: If goods < 2% turnover
A18: Legal services | C18: 14.5% | D18: 16.5% | E18: If goods < 2% turnover
A19: Business services (general) | C19: 12.0% | D19: 16.5% | E19: If goods < 2% turnover
A20: Catering / takeaway | C20: 12.5% | D20: 16.5% | E20: Includes hot food
A21: Retail — general | C21: 7.5% | D21: 16.5% | E21: Mixed goods
A22: Transport & logistics | C22: 10.0% | D22: 16.5% | E22: Road haulage
A23: Healthcare | C23: 12.0% | D23: 16.5% | E23: Registered practitioners
A24: Property letting | C24: 8.5% | D24: 16.5% | E24: VAT-registered lettings
... A28: Hotel / accommodation | C28: 10.5% | D28: 16.5% | E28: Room only
A31: VATflow by United Fintec Limited · contact@unitedfintec.com · unitedfintec.com · © 2025 United Fintec Limited

Sheet Scheme_Guide
A1: UK VAT ACCOUNTING SCHEMES — COMPLETE GUIDE
A2: Reference guide for all 5 HMRC VAT accounting schemes · Current rules 2025
A4: STANDARD (INVOICE BASIS)
A5: Field | B5: Detail
A6: VAT charged on | B6: All sales invoices issued in the period
A7: VAT reclaimed on | B7: All purchase invoices received in the period
A8: Box 1 | B8: Sum of VAT on all sales invoices
A9: Box 4 | B9: Sum of VAT on all purchase invoices
A10: Box 5 | B10: Box 3 − Box 4
A11: Key advantage | B11: Full input VAT recovery on all purchases
A12: Key consideration | B12: Pay VAT when invoiced — even if customer hasn't paid yet
A13: HMRC reference | B13: VAT Notice 700
A15: CASH ACCOUNTING SCHEME
A16: Field | B16: Detail
A17: VAT accounted | B17: When payment received (sales) / made (purchases)
A18: Box 1 | B18: VAT on payments received in period
A19: Box 4 | B19: VAT on payments made in period
A20: Key advantage | B20: Only pay VAT when customer pays you — helps cash flow
A21: Key consideration | B21: Cannot use if any customer owes more than £10,000 over 6 months
A22: Join/leave | B22: Join when turnover ≤ £1.35m. Leave if exceeds £1.6m.
A23: HMRC reference | B23: VAT Notice 731
A25: FLAT RATE SCHEME (FRS)
A26: Field | B26: Detail
A27: Box 1 | B27: Gross turnover (incl. VAT) × your flat rate %
A28: Box 4 | B28: Usually £0 — no input VAT recovery
A29: Exception | B29: Capital goods ≥ £2,000 incl. VAT: you CAN claim input VAT separately
A30: Limited Cost Trader | B30: If goods < 2% of turnover OR < £1,000/yr → use 16.5%
A31: First year discount | B31: New VAT registrations get 1% reduction in first year
A32: Profit | B32: Keep the difference between VAT charged (20%) and FRS rate
A33: Leave when | B33: Turnover exceeds £230,000. Must leave if expected to exceed.
A34: HMRC reference | B34: VAT Notice 733
A36: ANNUAL ACCOUNTING SCHEME
A37: Field | B37: Detail
A38: Returns | B38: One annual return covering the full 12-month period
A39: Advance payments | B39: 9 interim payments (10% of previous year's liability) months 4-12
A40: Balancing payment | B40: Due with annual return
A41: Advantage | B41: Reduces admin to a single annual filing
A42: Consideration | B42: You may overpay throughout the year if turnover drops
A43: Join/leave | B43: Join when turnover ≤ £1.35m. Leave if exceeds £1.6m.
A44: HMRC reference | B44: VAT Notice 732
...

Sheet Instructions
A1: USER GUIDE — HOW TO USE VATFLOW EXCEL TEMPLATE
A2: Follow these steps in order · Blue cells = you enter data · Green cells = auto-calculated, do not edit
A4: STEP 1 | C4: ENTER BUSINESS DETAILS ON DASHBOARD
B5: What to do | C5: Go to the DASHBOARD sheet (first tab)
B6: Enter | C6: Your business name, VAT registration number (VRN), company reg. number, address
B7: Check email | C7: Contact email should be contact@unitedfintec.com — update if needed
B8: Enter dates | C8: VAT period start date, end date, and submission due date
B9: Select scheme | C9: Choose your VAT accounting scheme from the dropdown (cell B15)
B10: FRS only | C10: If using Flat Rate Scheme, enter your sector percentage in cell B16 (e.g. 0.165 for 16.5%)
A12: STEP 2 | C12: ENTER YOUR SALES / INVOICES ON THE SALES SHEET
B13: Navigate | C13: Click the SALES tab
B14: Invoice No. | C14: Enter your invoice number in column B
B15: Customer | C15: Enter customer or client name in column C
B16: Date | C16: Enter the invoice date (date of supply) in column D — format DD/MM/YYYY
B17: Net Amount | C17: Enter the NET amount (excluding VAT) in column E — this is the only amount you type
B18: VAT Rate | C18: Select the VAT rate from the dropdown in column G: 0%, 5%, or 20%
B19: Auto-calculated | C19: Column H (VAT Amount) and column I (Gross Total) calculate automatically — do not edit
B20: EC Supply | C20: If goods were supplied to EU member states (post-Brexit exports), enter the net value in column J
B21: Category | C21: Select a category from the dropdown in column K
B22: FRS note | C22: For Flat Rate Scheme: Box 1 uses Gross Sales × FRS%. The VAT Amount column is still calculated but FRS uses gross × rate.
A24: STEP 3 | C24: ENTER YOUR EXPENSES / PURCHASES ON THE EXPENSES SHEET
B25: Navigate | C25: Click the EXPENSES tab
B26: Receipt/Invoice | C26: Enter the receipt or supplier invoice number in column B
B27: Supplier | C27: Enter the supplier name in column C
B28: Date | C28: Enter the purchase date in column D
B29: Net Amount | C29: Enter the NET purchase amount (excluding VAT) in column E
B30: VAT Rate | C30: Select the VAT rate from the dropdown in column G
B31: Reclaim Type | C31: IMPORTANT: Select the appropriate type in column K:
B32: → Claimable | C32: Standard / Cash / Annual / Retail schemes: select 'Claimable' for all business purchases
B33: → Not Claimable (FRS) | C33: Flat Rate Scheme traders: select 'Not Claimable (FRS)' for ALL normal purchases
B34: → Capital Goods FRS | C34: FRS only: if the purchase is a SINGLE item costing £2,000 or more (incl. VAT), select 'Capital Goods FRS' — you CAN reclaim VAT on this
B35: Auto-calculated | C35: Column H (VAT Amount) and column I (Gross Total) auto-calculate
A37: STEP 4 | C37: CHECK THE VAT_Return SHEET
B38: Navigate | C38: Click the VAT_Return tab
B39: Verify | C39: All 9 boxes should now show calculated values linked from your Sales and Expenses data
B40: Arithmetic checks | C40: Scroll down to the Arithmetic Validation section — all three checks should show ✓ PASS
B41: Box 5 | C41: This is your NET VAT PAYABLE. Positive = you owe HMRC. Negative = HMRC owes you a repayment.
B42: Do not edit | C42: GREEN cells are formulas. AMBER cells link from the Dashboard. Do not manually override.
B43: FRS users | C43: Box 4 will show £0 for FRS (this is correct unless you have Capital Goods exceptions).
A45: STEP 5 | C45: REVIEW THE DASHBOARD SUMMARY
...
